/bin/sh: xss-lock：未找到命令
(INFO-8411 addon.c:151) 加载附加组件配置文件: fcitx-googlepinyin.conf
(INFO-8411 addon.c:151) 加载附加组件配置文件: fcitx-dbus.conf
(INFO-8411 addon.c:151) 加载附加组件配置文件: fcitx-imselector.conf
(INFO-8411 addon.c:151) 加载附加组件配置文件: fcitx-kimpanel-ui.conf
(INFO-8411 addon.c:151) 加载附加组件配置文件: fcitx-fullwidth-char.conf
(INFO-8411 addon.c:151) 加载附加组件配置文件: fcitx-clipboard.conf
(INFO-8411 addon.c:151) 加载附加组件配置文件: fcitx-table.conf
(INFO-8411 addon.c:151) 加载附加组件配置文件: fcitx-xim.conf
(INFO-8411 addon.c:151) 加载附加组件配置文件: fcitx-remote-module.conf
(INFO-8411 addon.c:151) 加载附加组件配置文件: fcitx-autoeng.conf
(INFO-8411 addon.c:151) 加载附加组件配置文件: fcitx-pinyin-enhance.conf
(INFO-8411 addon.c:151) 加载附加组件配置文件: fcitx-ipcportal.conf
(INFO-8411 addon.c:151) 加载附加组件配置文件: fcitx-pinyin.conf
(INFO-8411 addon.c:151) 加载附加组件配置文件: fcitx-qw.conf
(INFO-8411 addon.c:151) 加载附加组件配置文件: fcitx-freedesktop-notify.conf
(INFO-8411 addon.c:151) 加载附加组件配置文件: fcitx-vk.conf
(INFO-8411 addon.c:151) 加载附加组件配置文件: fcitx-keyboard.conf
(INFO-8411 addon.c:151) 加载附加组件配置文件: fcitx-unicode.conf
(INFO-8411 addon.c:151) 加载附加组件配置文件: fcitx-punc.conf
(INFO-8411 addon.c:151) 加载附加组件配置文件: fcitx-xkb.conf
(INFO-8411 addon.c:151) 加载附加组件配置文件: fcitx-xkbdbus.conf
(INFO-8411 addon.c:151) 加载附加组件配置文件: fcitx-x11.conf
(INFO-8411 addon.c:151) 加载附加组件配置文件: fcitx-quickphrase.conf
(INFO-8411 addon.c:151) 加载附加组件配置文件: fcitx-spell.conf
(INFO-8411 addon.c:151) 加载附加组件配置文件: fcitx-ipc.conf
(INFO-8411 addon.c:151) 加载附加组件配置文件: fcitx-chttrans.conf
(INFO-8411 addon.c:151) 加载附加组件配置文件: fcitx-classic-ui.conf
(INFO-8411 addon.c:151) 加载附加组件配置文件: fcitx-notificationitem.conf
(ERROR-8411 ime.c:432) fcitx-keyboard-in-kan-kagapa already exists
(ERROR-8411 ime.c:432) fcitx-keyboard-in-tel-kagapa already exists
(ERROR-8411 ime.c:432) fcitx-keyboard-cm-mmuock already exists

(variety:8407): Gtk-WARNING **: 15:32:45.964: Theme parsing error: gtk.css:68:35: The style property GtkButton:child-displacement-x is deprecated and shouldn't be used anymore. It will be removed in a future version

(variety:8407): Gtk-WARNING **: 15:32:45.964: Theme parsing error: gtk.css:69:35: The style property GtkButton:child-displacement-y is deprecated and shouldn't be used anymore. It will be removed in a future version

(variety:8407): Gtk-WARNING **: 15:32:45.964: Theme parsing error: gtk.css:73:46: The style property GtkScrolledWindow:scrollbars-within-bevel is deprecated and shouldn't be used anymore. It will be removed in a future version
WARNING: 2019-08-21 15:32:46,251: create_menu() 'Variety Slideshow is not installed. This is an optional extension adding pan-and-zoom slideshows to Variety: see https://github.com/peterlevi/variety-slideshow for details'
ERROR: 2019-08-21 15:33:11,510: server_options_thread() 'Could not fetch Variety serverside options'
Traceback (most recent call last):
  File "/usr/lib/python3.7/site-packages/urllib3/connection.py", line 160, in _new_conn
    (self._dns_host, self.port), self.timeout, **extra_kw)
  File "/usr/lib/python3.7/site-packages/urllib3/util/connection.py", line 80, in create_connection
    raise err
  File "/usr/lib/python3.7/site-packages/urllib3/util/connection.py", line 70, in create_connection
    sock.connect(sa)
socket.timeout: timed out

During handling of the above exception, another exception occurred:

Traceback (most recent call last):
  File "/usr/lib/python3.7/site-packages/urllib3/connectionpool.py", line 603, in urlopen
    chunked=chunked)
  File "/usr/lib/python3.7/site-packages/urllib3/connectionpool.py", line 355, in _make_request
    conn.request(method, url, **httplib_request_kw)
  File "/usr/lib/python3.7/http/client.py", line 1244, in request
    self._send_request(method, url, body, headers, encode_chunked)
  File "/usr/lib/python3.7/http/client.py", line 1290, in _send_request
    self.endheaders(body, encode_chunked=encode_chunked)
  File "/usr/lib/python3.7/http/client.py", line 1239, in endheaders
    self._send_output(message_body, encode_chunked=encode_chunked)
  File "/usr/lib/python3.7/http/client.py", line 1026, in _send_output
    self.send(msg)
  File "/usr/lib/python3.7/http/client.py", line 966, in send
    self.connect()
  File "/usr/lib/python3.7/site-packages/urllib3/connection.py", line 183, in connect
    conn = self._new_conn()
  File "/usr/lib/python3.7/site-packages/urllib3/connection.py", line 165, in _new_conn
    (self.host, self.timeout))
urllib3.exceptions.ConnectTimeoutError: (<urllib3.connection.HTTPConnection object at 0x7f120c71f6d0>, 'Connection to tiny.cc timed out. (connect timeout=5)')

During handling of the above exception, another exception occurred:

Traceback (most recent call last):
  File "/usr/lib/python3.7/site-packages/requests/adapters.py", line 449, in send
    timeout=timeout
  File "/usr/lib/python3.7/site-packages/urllib3/connectionpool.py", line 641, in urlopen
    _stacktrace=sys.exc_info()[2])
  File "/usr/lib/python3.7/site-packages/urllib3/util/retry.py", line 399, in increment
    raise MaxRetryError(_pool, url, error or ResponseError(cause))
urllib3.exceptions.MaxRetryError: HTTPConnectionPool(host='tiny.cc', port=80): Max retries exceeded with url: /variety-options-063 (Caused by ConnectTimeoutError(<urllib3.connection.HTTPConnection object at 0x7f120c71f6d0>, 'Connection to tiny.cc timed out. (connect timeout=5)'))

During handling of the above exception, another exception occurred:

Traceback (most recent call last):
  File "/usr/lib/python3.7/site-packages/variety/VarietyWindow.py", line 939, in server_options_thread
    self.server_options = Util.fetch_json(VarietyWindow.SERVERSIDE_OPTIONS_URL)
  File "/usr/lib/python3.7/site-packages/variety/Util.py", line 593, in fetch_json
    return Util.request(url, data).json()
  File "/usr/lib/python3.7/site-packages/variety/Util.py", line 571, in request
    timeout=timeout)
  File "/usr/lib/python3.7/site-packages/requests/api.py", line 60, in request
    return session.request(method=method, url=url, **kwargs)
  File "/usr/lib/python3.7/site-packages/requests/sessions.py", line 533, in request
    resp = self.send(prep, **send_kwargs)
  File "/usr/lib/python3.7/site-packages/requests/sessions.py", line 646, in send
    r = adapter.send(request, **kwargs)
  File "/usr/lib/python3.7/site-packages/requests/adapters.py", line 504, in send
    raise ConnectTimeout(e, request=request)
requests.exceptions.ConnectTimeout: HTTPConnectionPool(host='tiny.cc', port=80): Max retries exceeded with url: /variety-options-063 (Caused by ConnectTimeoutError(<urllib3.connection.HTTPConnection object at 0x7f120c71f6d0>, 'Connection to tiny.cc timed out. (connect timeout=5)'))
ERROR: 2019-08-21 15:33:46,595: server_options_thread() 'Could not fetch Variety serverside options'
Traceback (most recent call last):
  File "/usr/lib/python3.7/site-packages/urllib3/connection.py", line 160, in _new_conn
    (self._dns_host, self.port), self.timeout, **extra_kw)
  File "/usr/lib/python3.7/site-packages/urllib3/util/connection.py", line 80, in create_connection
    raise err
  File "/usr/lib/python3.7/site-packages/urllib3/util/connection.py", line 70, in create_connection
    sock.connect(sa)
socket.timeout: timed out

During handling of the above exception, another exception occurred:

Traceback (most recent call last):
  File "/usr/lib/python3.7/site-packages/urllib3/connectionpool.py", line 603, in urlopen
    chunked=chunked)
  File "/usr/lib/python3.7/site-packages/urllib3/connectionpool.py", line 355, in _make_request
    conn.request(method, url, **httplib_request_kw)
  File "/usr/lib/python3.7/http/client.py", line 1244, in request
    self._send_request(method, url, body, headers, encode_chunked)
  File "/usr/lib/python3.7/http/client.py", line 1290, in _send_request
    self.endheaders(body, encode_chunked=encode_chunked)
  File "/usr/lib/python3.7/http/client.py", line 1239, in endheaders
    self._send_output(message_body, encode_chunked=encode_chunked)
  File "/usr/lib/python3.7/http/client.py", line 1026, in _send_output
    self.send(msg)
  File "/usr/lib/python3.7/http/client.py", line 966, in send
    self.connect()
  File "/usr/lib/python3.7/site-packages/urllib3/connection.py", line 183, in connect
    conn = self._new_conn()
  File "/usr/lib/python3.7/site-packages/urllib3/connection.py", line 165, in _new_conn
    (self.host, self.timeout))
urllib3.exceptions.ConnectTimeoutError: (<urllib3.connection.HTTPConnection object at 0x7f120c74b690>, 'Connection to tiny.cc timed out. (connect timeout=5)')

During handling of the above exception, another exception occurred:

Traceback (most recent call last):
  File "/usr/lib/python3.7/site-packages/requests/adapters.py", line 449, in send
    timeout=timeout
  File "/usr/lib/python3.7/site-packages/urllib3/connectionpool.py", line 641, in urlopen
    _stacktrace=sys.exc_info()[2])
  File "/usr/lib/python3.7/site-packages/urllib3/util/retry.py", line 399, in increment
    raise MaxRetryError(_pool, url, error or ResponseError(cause))
urllib3.exceptions.MaxRetryError: HTTPConnectionPool(host='tiny.cc', port=80): Max retries exceeded with url: /variety-options-063 (Caused by ConnectTimeoutError(<urllib3.connection.HTTPConnection object at 0x7f120c74b690>, 'Connection to tiny.cc timed out. (connect timeout=5)'))

During handling of the above exception, another exception occurred:

Traceback (most recent call last):
  File "/usr/lib/python3.7/site-packages/variety/VarietyWindow.py", line 939, in server_options_thread
    self.server_options = Util.fetch_json(VarietyWindow.SERVERSIDE_OPTIONS_URL)
  File "/usr/lib/python3.7/site-packages/variety/Util.py", line 593, in fetch_json
    return Util.request(url, data).json()
  File "/usr/lib/python3.7/site-packages/variety/Util.py", line 571, in request
    timeout=timeout)
  File "/usr/lib/python3.7/site-packages/requests/api.py", line 60, in request
    return session.request(method=method, url=url, **kwargs)
  File "/usr/lib/python3.7/site-packages/requests/sessions.py", line 533, in request
    resp = self.send(prep, **send_kwargs)
  File "/usr/lib/python3.7/site-packages/requests/sessions.py", line 646, in send
    r = adapter.send(request, **kwargs)
  File "/usr/lib/python3.7/site-packages/requests/adapters.py", line 504, in send
    raise ConnectTimeout(e, request=request)
requests.exceptions.ConnectTimeout: HTTPConnectionPool(host='tiny.cc', port=80): Max retries exceeded with url: /variety-options-063 (Caused by ConnectTimeoutError(<urllib3.connection.HTTPConnection object at 0x7f120c74b690>, 'Connection to tiny.cc timed out. (connect timeout=5)'))
ERROR: 2019-08-21 15:34:21,645: server_options_thread() 'Could not fetch Variety serverside options'
Traceback (most recent call last):
  File "/usr/lib/python3.7/site-packages/urllib3/connection.py", line 160, in _new_conn
    (self._dns_host, self.port), self.timeout, **extra_kw)
  File "/usr/lib/python3.7/site-packages/urllib3/util/connection.py", line 80, in create_connection
    raise err
  File "/usr/lib/python3.7/site-packages/urllib3/util/connection.py", line 70, in create_connection
    sock.connect(sa)
socket.timeout: timed out

During handling of the above exception, another exception occurred:

Traceback (most recent call last):
  File "/usr/lib/python3.7/site-packages/urllib3/connectionpool.py", line 603, in urlopen
    chunked=chunked)
  File "/usr/lib/python3.7/site-packages/urllib3/connectionpool.py", line 355, in _make_request
    conn.request(method, url, **httplib_request_kw)
  File "/usr/lib/python3.7/http/client.py", line 1244, in request
    self._send_request(method, url, body, headers, encode_chunked)
  File "/usr/lib/python3.7/http/client.py", line 1290, in _send_request
    self.endheaders(body, encode_chunked=encode_chunked)
  File "/usr/lib/python3.7/http/client.py", line 1239, in endheaders
    self._send_output(message_body, encode_chunked=encode_chunked)
  File "/usr/lib/python3.7/http/client.py", line 1026, in _send_output
    self.send(msg)
  File "/usr/lib/python3.7/http/client.py", line 966, in send
    self.connect()
  File "/usr/lib/python3.7/site-packages/urllib3/connection.py", line 183, in connect
    conn = self._new_conn()
  File "/usr/lib/python3.7/site-packages/urllib3/connection.py", line 165, in _new_conn
    (self.host, self.timeout))
urllib3.exceptions.ConnectTimeoutError: (<urllib3.connection.HTTPConnection object at 0x7f12281df910>, 'Connection to tiny.cc timed out. (connect timeout=5)')

During handling of the above exception, another exception occurred:

Traceback (most recent call last):
  File "/usr/lib/python3.7/site-packages/requests/adapters.py", line 449, in send
    timeout=timeout
  File "/usr/lib/python3.7/site-packages/urllib3/connectionpool.py", line 641, in urlopen
    _stacktrace=sys.exc_info()[2])
  File "/usr/lib/python3.7/site-packages/urllib3/util/retry.py", line 399, in increment
    raise MaxRetryError(_pool, url, error or ResponseError(cause))
urllib3.exceptions.MaxRetryError: HTTPConnectionPool(host='tiny.cc', port=80): Max retries exceeded with url: /variety-options-063 (Caused by ConnectTimeoutError(<urllib3.connection.HTTPConnection object at 0x7f12281df910>, 'Connection to tiny.cc timed out. (connect timeout=5)'))

During handling of the above exception, another exception occurred:

Traceback (most recent call last):
  File "/usr/lib/python3.7/site-packages/variety/VarietyWindow.py", line 939, in server_options_thread
    self.server_options = Util.fetch_json(VarietyWindow.SERVERSIDE_OPTIONS_URL)
  File "/usr/lib/python3.7/site-packages/variety/Util.py", line 593, in fetch_json
    return Util.request(url, data).json()
  File "/usr/lib/python3.7/site-packages/variety/Util.py", line 571, in request
    timeout=timeout)
  File "/usr/lib/python3.7/site-packages/requests/api.py", line 60, in request
    return session.request(method=method, url=url, **kwargs)
  File "/usr/lib/python3.7/site-packages/requests/sessions.py", line 533, in request
    resp = self.send(prep, **send_kwargs)
  File "/usr/lib/python3.7/site-packages/requests/sessions.py", line 646, in send
    r = adapter.send(request, **kwargs)
  File "/usr/lib/python3.7/site-packages/requests/adapters.py", line 504, in send
    raise ConnectTimeout(e, request=request)
requests.exceptions.ConnectTimeout: HTTPConnectionPool(host='tiny.cc', port=80): Max retries exceeded with url: /variety-options-063 (Caused by ConnectTimeoutError(<urllib3.connection.HTTPConnection object at 0x7f12281df910>, 'Connection to tiny.cc timed out. (connect timeout=5)'))
ERROR: 2019-08-21 15:34:56,693: server_options_thread() 'Could not fetch Variety serverside options'
Traceback (most recent call last):
  File "/usr/lib/python3.7/site-packages/urllib3/connection.py", line 160, in _new_conn
    (self._dns_host, self.port), self.timeout, **extra_kw)
  File "/usr/lib/python3.7/site-packages/urllib3/util/connection.py", line 80, in create_connection
    raise err
  File "/usr/lib/python3.7/site-packages/urllib3/util/connection.py", line 70, in create_connection
    sock.connect(sa)
socket.timeout: timed out

During handling of the above exception, another exception occurred:

Traceback (most recent call last):
  File "/usr/lib/python3.7/site-packages/urllib3/connectionpool.py", line 603, in urlopen
    chunked=chunked)
  File "/usr/lib/python3.7/site-packages/urllib3/connectionpool.py", line 355, in _make_request
    conn.request(method, url, **httplib_request_kw)
  File "/usr/lib/python3.7/http/client.py", line 1244, in request
    self._send_request(method, url, body, headers, encode_chunked)
  File "/usr/lib/python3.7/http/client.py", line 1290, in _send_request
    self.endheaders(body, encode_chunked=encode_chunked)
  File "/usr/lib/python3.7/http/client.py", line 1239, in endheaders
    self._send_output(message_body, encode_chunked=encode_chunked)
  File "/usr/lib/python3.7/http/client.py", line 1026, in _send_output
    self.send(msg)
  File "/usr/lib/python3.7/http/client.py", line 966, in send
    self.connect()
  File "/usr/lib/python3.7/site-packages/urllib3/connection.py", line 183, in connect
    conn = self._new_conn()
  File "/usr/lib/python3.7/site-packages/urllib3/connection.py", line 165, in _new_conn
    (self.host, self.timeout))
urllib3.exceptions.ConnectTimeoutError: (<urllib3.connection.HTTPConnection object at 0x7f120c74b210>, 'Connection to tiny.cc timed out. (connect timeout=5)')

During handling of the above exception, another exception occurred:

Traceback (most recent call last):
  File "/usr/lib/python3.7/site-packages/requests/adapters.py", line 449, in send
    timeout=timeout
  File "/usr/lib/python3.7/site-packages/urllib3/connectionpool.py", line 641, in urlopen
    _stacktrace=sys.exc_info()[2])
  File "/usr/lib/python3.7/site-packages/urllib3/util/retry.py", line 399, in increment
    raise MaxRetryError(_pool, url, error or ResponseError(cause))
urllib3.exceptions.MaxRetryError: HTTPConnectionPool(host='tiny.cc', port=80): Max retries exceeded with url: /variety-options-063 (Caused by ConnectTimeoutError(<urllib3.connection.HTTPConnection object at 0x7f120c74b210>, 'Connection to tiny.cc timed out. (connect timeout=5)'))

During handling of the above exception, another exception occurred:

Traceback (most recent call last):
  File "/usr/lib/python3.7/site-packages/variety/VarietyWindow.py", line 939, in server_options_thread
    self.server_options = Util.fetch_json(VarietyWindow.SERVERSIDE_OPTIONS_URL)
  File "/usr/lib/python3.7/site-packages/variety/Util.py", line 593, in fetch_json
    return Util.request(url, data).json()
  File "/usr/lib/python3.7/site-packages/variety/Util.py", line 571, in request
    timeout=timeout)
  File "/usr/lib/python3.7/site-packages/requests/api.py", line 60, in request
    return session.request(method=method, url=url, **kwargs)
  File "/usr/lib/python3.7/site-packages/requests/sessions.py", line 533, in request
    resp = self.send(prep, **send_kwargs)
  File "/usr/lib/python3.7/site-packages/requests/sessions.py", line 646, in send
    r = adapter.send(request, **kwargs)
  File "/usr/lib/python3.7/site-packages/requests/adapters.py", line 504, in send
    raise ConnectTimeout(e, request=request)
requests.exceptions.ConnectTimeout: HTTPConnectionPool(host='tiny.cc', port=80): Max retries exceeded with url: /variety-options-063 (Caused by ConnectTimeoutError(<urllib3.connection.HTTPConnection object at 0x7f120c74b210>, 'Connection to tiny.cc timed out. (connect timeout=5)'))
ERROR: 2019-08-21 15:35:31,744: server_options_thread() 'Could not fetch Variety serverside options'
Traceback (most recent call last):
  File "/usr/lib/python3.7/site-packages/urllib3/connection.py", line 160, in _new_conn
    (self._dns_host, self.port), self.timeout, **extra_kw)
  File "/usr/lib/python3.7/site-packages/urllib3/util/connection.py", line 80, in create_connection
    raise err
  File "/usr/lib/python3.7/site-packages/urllib3/util/connection.py", line 70, in create_connection
    sock.connect(sa)
socket.timeout: timed out

During handling of the above exception, another exception occurred:

Traceback (most recent call last):
  File "/usr/lib/python3.7/site-packages/urllib3/connectionpool.py", line 603, in urlopen
    chunked=chunked)
  File "/usr/lib/python3.7/site-packages/urllib3/connectionpool.py", line 355, in _make_request
    conn.request(method, url, **httplib_request_kw)
  File "/usr/lib/python3.7/http/client.py", line 1244, in request
    self._send_request(method, url, body, headers, encode_chunked)
  File "/usr/lib/python3.7/http/client.py", line 1290, in _send_request
    self.endheaders(body, encode_chunked=encode_chunked)
  File "/usr/lib/python3.7/http/client.py", line 1239, in endheaders
    self._send_output(message_body, encode_chunked=encode_chunked)
  File "/usr/lib/python3.7/http/client.py", line 1026, in _send_output
    self.send(msg)
  File "/usr/lib/python3.7/http/client.py", line 966, in send
    self.connect()
  File "/usr/lib/python3.7/site-packages/urllib3/connection.py", line 183, in connect
    conn = self._new_conn()
  File "/usr/lib/python3.7/site-packages/urllib3/connection.py", line 165, in _new_conn
    (self.host, self.timeout))
urllib3.exceptions.ConnectTimeoutError: (<urllib3.connection.HTTPConnection object at 0x7f120c748190>, 'Connection to tiny.cc timed out. (connect timeout=5)')

During handling of the above exception, another exception occurred:

Traceback (most recent call last):
  File "/usr/lib/python3.7/site-packages/requests/adapters.py", line 449, in send
    timeout=timeout
  File "/usr/lib/python3.7/site-packages/urllib3/connectionpool.py", line 641, in urlopen
    _stacktrace=sys.exc_info()[2])
  File "/usr/lib/python3.7/site-packages/urllib3/util/retry.py", line 399, in increment
    raise MaxRetryError(_pool, url, error or ResponseError(cause))
urllib3.exceptions.MaxRetryError: HTTPConnectionPool(host='tiny.cc', port=80): Max retries exceeded with url: /variety-options-063 (Caused by ConnectTimeoutError(<urllib3.connection.HTTPConnection object at 0x7f120c748190>, 'Connection to tiny.cc timed out. (connect timeout=5)'))

During handling of the above exception, another exception occurred:

Traceback (most recent call last):
  File "/usr/lib/python3.7/site-packages/variety/VarietyWindow.py", line 939, in server_options_thread
    self.server_options = Util.fetch_json(VarietyWindow.SERVERSIDE_OPTIONS_URL)
  File "/usr/lib/python3.7/site-packages/variety/Util.py", line 593, in fetch_json
    return Util.request(url, data).json()
  File "/usr/lib/python3.7/site-packages/variety/Util.py", line 571, in request
    timeout=timeout)
  File "/usr/lib/python3.7/site-packages/requests/api.py", line 60, in request
    return session.request(method=method, url=url, **kwargs)
  File "/usr/lib/python3.7/site-packages/requests/sessions.py", line 533, in request
    resp = self.send(prep, **send_kwargs)
  File "/usr/lib/python3.7/site-packages/requests/sessions.py", line 646, in send
    r = adapter.send(request, **kwargs)
  File "/usr/lib/python3.7/site-packages/requests/adapters.py", line 504, in send
    raise ConnectTimeout(e, request=request)
requests.exceptions.ConnectTimeout: HTTPConnectionPool(host='tiny.cc', port=80): Max retries exceeded with url: /variety-options-063 (Caused by ConnectTimeoutError(<urllib3.connection.HTTPConnection object at 0x7f120c748190>, 'Connection to tiny.cc timed out. (connect timeout=5)'))
ERROR: 2019-08-21 15:37:47,465: download_thread() 'Could not download wallpaper:'
Traceback (most recent call last):
  File "/usr/lib/python3.7/site-packages/variety/VarietyWindow.py", line 991, in download_thread
    dl.download_one()
  File "/usr/lib/python3.7/site-packages/variety/EarthDownloader.py", line 39, in download_one
    downloaded = self.save_locally(self.location, EARTH_IMAGE_URL, force_download=True, extra_metadata={'headline': 'World Sunlight Map'})
  File "/usr/lib/python3.7/site-packages/variety/Downloader.py", line 117, in save_locally
    raise e
  File "/usr/lib/python3.7/site-packages/variety/Downloader.py", line 112, in save_locally
    r = Util.request(image_url, stream=True)
  File "/usr/lib/python3.7/site-packages/variety/Util.py", line 572, in request
    r.raise_for_status()
  File "/usr/lib/python3.7/site-packages/requests/models.py", line 940, in raise_for_status
    raise HTTPError(http_error_msg, response=self)
requests.exceptions.HTTPError: 503 Server Error: Service Temporarily Unavailable for url: https://static.die.net/earth/mercator/1600.jpg
ERROR: 2019-08-21 15:43:03,074: download_thread() 'Could not download wallpaper:'
Traceback (most recent call last):
  File "/usr/lib/python3.7/site-packages/variety/VarietyWindow.py", line 991, in download_thread
    dl.download_one()
  File "/usr/lib/python3.7/site-packages/variety/EarthDownloader.py", line 39, in download_one
    downloaded = self.save_locally(self.location, EARTH_IMAGE_URL, force_download=True, extra_metadata={'headline': 'World Sunlight Map'})
  File "/usr/lib/python3.7/site-packages/variety/Downloader.py", line 117, in save_locally
    raise e
  File "/usr/lib/python3.7/site-packages/variety/Downloader.py", line 112, in save_locally
    r = Util.request(image_url, stream=True)
  File "/usr/lib/python3.7/site-packages/variety/Util.py", line 572, in request
    r.raise_for_status()
  File "/usr/lib/python3.7/site-packages/requests/models.py", line 940, in raise_for_status
    raise HTTPError(http_error_msg, response=self)
requests.exceptions.HTTPError: 503 Server Error: Service Temporarily Unavailable for url: https://static.die.net/earth/mercator/1600.jpg
ERROR: 2019-08-21 15:47:46,899: request() 'SSL Error for url https://api.desktoppr.co/1/wallpapers/random:'
Traceback (most recent call last):
  File "/usr/lib/python3.7/site-packages/urllib3/connectionpool.py", line 603, in urlopen
    chunked=chunked)
  File "/usr/lib/python3.7/site-packages/urllib3/connectionpool.py", line 344, in _make_request
    self._validate_conn(conn)
  File "/usr/lib/python3.7/site-packages/urllib3/connectionpool.py", line 843, in _validate_conn
    conn.connect()
  File "/usr/lib/python3.7/site-packages/urllib3/connection.py", line 370, in connect
    ssl_context=context)
  File "/usr/lib/python3.7/site-packages/urllib3/util/ssl_.py", line 355, in ssl_wrap_socket
    return context.wrap_socket(sock, server_hostname=server_hostname)
  File "/usr/lib/python3.7/ssl.py", line 423, in wrap_socket
    session=session
  File "/usr/lib/python3.7/ssl.py", line 870, in _create
    self.do_handshake()
  File "/usr/lib/python3.7/ssl.py", line 1139, in do_handshake
    self._sslobj.do_handshake()
ssl.SSLCertVerificationError: [SSL: CERTIFICATE_VERIFY_FAILED] certificate verify failed: certificate has expired (_ssl.c:1076)

During handling of the above exception, another exception occurred:

Traceback (most recent call last):
  File "/usr/lib/python3.7/site-packages/requests/adapters.py", line 449, in send
    timeout=timeout
  File "/usr/lib/python3.7/site-packages/urllib3/connectionpool.py", line 641, in urlopen
    _stacktrace=sys.exc_info()[2])
  File "/usr/lib/python3.7/site-packages/urllib3/util/retry.py", line 399, in increment
    raise MaxRetryError(_pool, url, error or ResponseError(cause))
urllib3.exceptions.MaxRetryError: HTTPSConnectionPool(host='api.desktoppr.co', port=443): Max retries exceeded with url: /1/wallpapers/random (Caused by SSLError(SSLCertVerificationError(1, '[SSL: CERTIFICATE_VERIFY_FAILED] certificate verify failed: certificate has expired (_ssl.c:1076)')))

During handling of the above exception, another exception occurred:

Traceback (most recent call last):
  File "/usr/lib/python3.7/site-packages/variety/Util.py", line 571, in request
    timeout=timeout)
  File "/usr/lib/python3.7/site-packages/requests/api.py", line 60, in request
    return session.request(method=method, url=url, **kwargs)
  File "/usr/lib/python3.7/site-packages/requests/sessions.py", line 533, in request
    resp = self.send(prep, **send_kwargs)
  File "/usr/lib/python3.7/site-packages/requests/sessions.py", line 646, in send
    r = adapter.send(request, **kwargs)
  File "/usr/lib/python3.7/site-packages/requests/adapters.py", line 514, in send
    raise SSLError(e, request=request)
requests.exceptions.SSLError: HTTPSConnectionPool(host='api.desktoppr.co', port=443): Max retries exceeded with url: /1/wallpapers/random (Caused by SSLError(SSLCertVerificationError(1, '[SSL: CERTIFICATE_VERIFY_FAILED] certificate verify failed: certificate has expired (_ssl.c:1076)')))
ERROR: 2019-08-21 15:47:46,902: download_thread() 'Could not download wallpaper:'
Traceback (most recent call last):
  File "/usr/lib/python3.7/site-packages/urllib3/connectionpool.py", line 603, in urlopen
    chunked=chunked)
  File "/usr/lib/python3.7/site-packages/urllib3/connectionpool.py", line 344, in _make_request
    self._validate_conn(conn)
  File "/usr/lib/python3.7/site-packages/urllib3/connectionpool.py", line 843, in _validate_conn
    conn.connect()
  File "/usr/lib/python3.7/site-packages/urllib3/connection.py", line 370, in connect
    ssl_context=context)
  File "/usr/lib/python3.7/site-packages/urllib3/util/ssl_.py", line 355, in ssl_wrap_socket
    return context.wrap_socket(sock, server_hostname=server_hostname)
  File "/usr/lib/python3.7/ssl.py", line 423, in wrap_socket
    session=session
  File "/usr/lib/python3.7/ssl.py", line 870, in _create
    self.do_handshake()
  File "/usr/lib/python3.7/ssl.py", line 1139, in do_handshake
    self._sslobj.do_handshake()
ssl.SSLCertVerificationError: [SSL: CERTIFICATE_VERIFY_FAILED] certificate verify failed: certificate has expired (_ssl.c:1076)

During handling of the above exception, another exception occurred:

Traceback (most recent call last):
  File "/usr/lib/python3.7/site-packages/requests/adapters.py", line 449, in send
    timeout=timeout
  File "/usr/lib/python3.7/site-packages/urllib3/connectionpool.py", line 641, in urlopen
    _stacktrace=sys.exc_info()[2])
  File "/usr/lib/python3.7/site-packages/urllib3/util/retry.py", line 399, in increment
    raise MaxRetryError(_pool, url, error or ResponseError(cause))
urllib3.exceptions.MaxRetryError: HTTPSConnectionPool(host='api.desktoppr.co', port=443): Max retries exceeded with url: /1/wallpapers/random (Caused by SSLError(SSLCertVerificationError(1, '[SSL: CERTIFICATE_VERIFY_FAILED] certificate verify failed: certificate has expired (_ssl.c:1076)')))

During handling of the above exception, another exception occurred:

Traceback (most recent call last):
  File "/usr/lib/python3.7/site-packages/variety/VarietyWindow.py", line 986, in download_thread
    self.download_one_from(downloader)
  File "/usr/lib/python3.7/site-packages/variety/VarietyWindow.py", line 1018, in download_one_from
    file = downloader.download_one()
  File "/usr/lib/python3.7/site-packages/variety/DesktopprDownloader.py", line 35, in download_one
    response = Util.fetch_json(self.location)
  File "/usr/lib/python3.7/site-packages/variety/Util.py", line 593, in fetch_json
    return Util.request(url, data).json()
  File "/usr/lib/python3.7/site-packages/variety/Util.py", line 571, in request
    timeout=timeout)
  File "/usr/lib/python3.7/site-packages/requests/api.py", line 60, in request
    return session.request(method=method, url=url, **kwargs)
  File "/usr/lib/python3.7/site-packages/requests/sessions.py", line 533, in request
    resp = self.send(prep, **send_kwargs)
  File "/usr/lib/python3.7/site-packages/requests/sessions.py", line 646, in send
    r = adapter.send(request, **kwargs)
  File "/usr/lib/python3.7/site-packages/requests/adapters.py", line 514, in send
    raise SSLError(e, request=request)
requests.exceptions.SSLError: HTTPSConnectionPool(host='api.desktoppr.co', port=443): Max retries exceeded with url: /1/wallpapers/random (Caused by SSLError(SSLCertVerificationError(1, '[SSL: CERTIFICATE_VERIFY_FAILED] certificate verify failed: certificate has expired (_ssl.c:1076)')))
ERROR: 2019-08-21 15:52:49,143: download_thread() 'Could not download wallpaper:'
Traceback (most recent call last):
  File "/usr/lib/python3.7/site-packages/variety/VarietyWindow.py", line 991, in download_thread
    dl.download_one()
  File "/usr/lib/python3.7/site-packages/variety/EarthDownloader.py", line 39, in download_one
    downloaded = self.save_locally(self.location, EARTH_IMAGE_URL, force_download=True, extra_metadata={'headline': 'World Sunlight Map'})
  File "/usr/lib/python3.7/site-packages/variety/Downloader.py", line 117, in save_locally
    raise e
  File "/usr/lib/python3.7/site-packages/variety/Downloader.py", line 112, in save_locally
    r = Util.request(image_url, stream=True)
  File "/usr/lib/python3.7/site-packages/variety/Util.py", line 572, in request
    r.raise_for_status()
  File "/usr/lib/python3.7/site-packages/requests/models.py", line 940, in raise_for_status
    raise HTTPError(http_error_msg, response=self)
requests.exceptions.HTTPError: 503 Server Error: Service Temporarily Unavailable for url: https://static.die.net/earth/mercator/1600.jpg
[ 2019年08月21日 15:56:44.767 glx_bind_pixmap ERROR ] Failed to query info of pixmap 0x006030e8.
[ 2019年08月21日 15:56:44.767 paint_one ERROR ] Failed to bind texture for window 0x02800018.
[ 2019年08月21日 15:56:44.767 paint_one ERROR ] Window 0x02800018 is missing painting data.
ERROR: 2019-08-21 15:57:47,140: download_thread() 'Could not download wallpaper:'
Traceback (most recent call last):
  File "/usr/lib/python3.7/site-packages/variety/VarietyWindow.py", line 991, in download_thread
    dl.download_one()
  File "/usr/lib/python3.7/site-packages/variety/EarthDownloader.py", line 39, in download_one
    downloaded = self.save_locally(self.location, EARTH_IMAGE_URL, force_download=True, extra_metadata={'headline': 'World Sunlight Map'})
  File "/usr/lib/python3.7/site-packages/variety/Downloader.py", line 117, in save_locally
    raise e
  File "/usr/lib/python3.7/site-packages/variety/Downloader.py", line 112, in save_locally
    r = Util.request(image_url, stream=True)
  File "/usr/lib/python3.7/site-packages/variety/Util.py", line 572, in request
    r.raise_for_status()
  File "/usr/lib/python3.7/site-packages/requests/models.py", line 940, in raise_for_status
    raise HTTPError(http_error_msg, response=self)
requests.exceptions.HTTPError: 503 Server Error: Service Temporarily Unavailable for url: https://static.die.net/earth/mercator/1600.jpg
